2019-02-19 13:07:26,119 ERROR: Exception on /export_posts [GET] [in /Users/youns/Documents/Vuno/flask_tutorial/venv/lib/python3.7/site-packages/flask/app.py:1761]
Traceback (most recent call last):
  File "/Users/youns/Documents/Vuno/flask_tutorial/venv/lib/python3.7/site-packages/redis/connection.py", line 492, in connect
    sock = self._connect()
  File "/Users/youns/Documents/Vuno/flask_tutorial/venv/lib/python3.7/site-packages/redis/connection.py", line 550, in _connect
    raise err
  File "/Users/youns/Documents/Vuno/flask_tutorial/venv/lib/python3.7/site-packages/redis/connection.py", line 538, in _connect
    sock.connect(socket_address)
ConnectionRefusedError: [Errno 61] Connection refused

During handling of the above exception, another exception occurred:

Traceback (most recent call last):
  File "/Users/youns/Documents/Vuno/flask_tutorial/venv/lib/python3.7/site-packages/flask/app.py", line 2292, in wsgi_app
    response = self.full_dispatch_request()
  File "/Users/youns/Documents/Vuno/flask_tutorial/venv/lib/python3.7/site-packages/flask/app.py", line 1815, in full_dispatch_request
    rv = self.handle_user_exception(e)
  File "/Users/youns/Documents/Vuno/flask_tutorial/venv/lib/python3.7/site-packages/flask/app.py", line 1718, in handle_user_exception
    reraise(exc_type, exc_value, tb)
  File "/Users/youns/Documents/Vuno/flask_tutorial/venv/lib/python3.7/site-packages/flask/_compat.py", line 35, in reraise
    raise value
  File "/Users/youns/Documents/Vuno/flask_tutorial/venv/lib/python3.7/site-packages/flask/app.py", line 1813, in full_dispatch_request
    rv = self.dispatch_request()
  File "/Users/youns/Documents/Vuno/flask_tutorial/venv/lib/python3.7/site-packages/flask/app.py", line 1799, in dispatch_request
    return self.view_functions[rule.endpoint](**req.view_args)
  File "/Users/youns/Documents/Vuno/flask_tutorial/venv/lib/python3.7/site-packages/flask_login/utils.py", line 261, in decorated_view
    return func(*args, **kwargs)
  File "/Users/youns/Documents/Vuno/flask_tutorial/app/main/routes.py", line 207, in export_posts
    current_user.launch_task('export_posts', _('Exporting posts...'))
  File "/Users/youns/Documents/Vuno/flask_tutorial/app/models.py", line 107, in launch_task
    *args, **kwargs)
  File "/Users/youns/Documents/Vuno/flask_tutorial/venv/lib/python3.7/site-packages/rq/queue.py", line 316, in enqueue
    job_id=job_id, at_front=at_front, meta=meta)
  File "/Users/youns/Documents/Vuno/flask_tutorial/venv/lib/python3.7/site-packages/rq/queue.py", line 263, in enqueue_call
    job = self.enqueue_job(job, at_front=at_front)
  File "/Users/youns/Documents/Vuno/flask_tutorial/venv/lib/python3.7/site-packages/rq/queue.py", line 341, in enqueue_job
    pipe.execute()
  File "/Users/youns/Documents/Vuno/flask_tutorial/venv/lib/python3.7/site-packages/redis/client.py", line 3514, in execute
    self.shard_hint)
  File "/Users/youns/Documents/Vuno/flask_tutorial/venv/lib/python3.7/site-packages/redis/connection.py", line 994, in get_connection
    connection.connect()
  File "/Users/youns/Documents/Vuno/flask_tutorial/venv/lib/python3.7/site-packages/redis/connection.py", line 497, in connect
    raise ConnectionError(self._error_message(e))
redis.exceptions.ConnectionError: Error 61 connecting to None:6379. Connection refused.
2019-02-19 13:07:56,151 ERROR: Exception on /export_posts [GET] [in /Users/youns/Documents/Vuno/flask_tutorial/venv/lib/python3.7/site-packages/flask/app.py:1761]
Traceback (most recent call last):
  File "/Users/youns/Documents/Vuno/flask_tutorial/venv/lib/python3.7/site-packages/redis/connection.py", line 492, in connect
    sock = self._connect()
  File "/Users/youns/Documents/Vuno/flask_tutorial/venv/lib/python3.7/site-packages/redis/connection.py", line 550, in _connect
    raise err
  File "/Users/youns/Documents/Vuno/flask_tutorial/venv/lib/python3.7/site-packages/redis/connection.py", line 538, in _connect
    sock.connect(socket_address)
ConnectionRefusedError: [Errno 61] Connection refused

During handling of the above exception, another exception occurred:

Traceback (most recent call last):
  File "/Users/youns/Documents/Vuno/flask_tutorial/venv/lib/python3.7/site-packages/flask/app.py", line 2292, in wsgi_app
    response = self.full_dispatch_request()
  File "/Users/youns/Documents/Vuno/flask_tutorial/venv/lib/python3.7/site-packages/flask/app.py", line 1815, in full_dispatch_request
    rv = self.handle_user_exception(e)
  File "/Users/youns/Documents/Vuno/flask_tutorial/venv/lib/python3.7/site-packages/flask/app.py", line 1718, in handle_user_exception
    reraise(exc_type, exc_value, tb)
  File "/Users/youns/Documents/Vuno/flask_tutorial/venv/lib/python3.7/site-packages/flask/_compat.py", line 35, in reraise
    raise value
  File "/Users/youns/Documents/Vuno/flask_tutorial/venv/lib/python3.7/site-packages/flask/app.py", line 1813, in full_dispatch_request
    rv = self.dispatch_request()
  File "/Users/youns/Documents/Vuno/flask_tutorial/venv/lib/python3.7/site-packages/flask/app.py", line 1799, in dispatch_request
    return self.view_functions[rule.endpoint](**req.view_args)
  File "/Users/youns/Documents/Vuno/flask_tutorial/venv/lib/python3.7/site-packages/flask_login/utils.py", line 261, in decorated_view
    return func(*args, **kwargs)
  File "/Users/youns/Documents/Vuno/flask_tutorial/app/main/routes.py", line 207, in export_posts
    current_user.launch_task('export_posts', _('Exporting posts...'))
  File "/Users/youns/Documents/Vuno/flask_tutorial/app/models.py", line 107, in launch_task
    *args, **kwargs)
  File "/Users/youns/Documents/Vuno/flask_tutorial/venv/lib/python3.7/site-packages/rq/queue.py", line 316, in enqueue
    job_id=job_id, at_front=at_front, meta=meta)
  File "/Users/youns/Documents/Vuno/flask_tutorial/venv/lib/python3.7/site-packages/rq/queue.py", line 263, in enqueue_call
    job = self.enqueue_job(job, at_front=at_front)
  File "/Users/youns/Documents/Vuno/flask_tutorial/venv/lib/python3.7/site-packages/rq/queue.py", line 341, in enqueue_job
    pipe.execute()
  File "/Users/youns/Documents/Vuno/flask_tutorial/venv/lib/python3.7/site-packages/redis/client.py", line 3514, in execute
    self.shard_hint)
  File "/Users/youns/Documents/Vuno/flask_tutorial/venv/lib/python3.7/site-packages/redis/connection.py", line 994, in get_connection
    connection.connect()
  File "/Users/youns/Documents/Vuno/flask_tutorial/venv/lib/python3.7/site-packages/redis/connection.py", line 497, in connect
    raise ConnectionError(self._error_message(e))
redis.exceptions.ConnectionError: Error 61 connecting to None:6379. Connection refused.
2019-02-19 13:09:27,014 INFO: Microblog startup [in /Users/youns/Documents/Vuno/flask_tutorial/app/__init__.py:82]
2019-02-19 13:09:34,778 INFO: Microblog startup [in /Users/youns/Documents/Vuno/flask_tutorial/app/__init__.py:82]
2019-02-19 13:11:07,639 INFO: Microblog startup [in ./app/__init__.py:82]
2019-02-19 13:11:12,676 INFO: Microblog startup [in /Users/youns/Documents/Vuno/flask_tutorial/app/__init__.py:82]
2019-02-19 13:11:32,675 INFO: Microblog startup [in ./app/__init__.py:82]
2019-02-19 13:11:32,703 ERROR: Unhandled exception [in ./app/tasks.py:63]
Traceback (most recent call last):
  File "./app/tasks.py", line 40, in export_posts
    user = User.query.get(user_id)
NameError: name 'User' is not defined
